Workbook
Name _Toc112498976: Data!$B$32
Name _Toc112498999: Data!$B$57
Name _Toc112499002: Data!$B$59
Name _Toc112499015: Data!#REF!
Name _Toc121086323: Data!$B$61
Name a: 'G1.5P'!#REF!
Name a: G1R!#REF!

Sheet G1R
A2: Gate 1 Technical Report Rubric
A3: Category | B3: Report Sec.# | C3: Title | D3: Requirements (Additional information provided in Guidelines_Report.doc) | E3: Meets Expectations (12) | F3: (11) | G3: (10) | H3: (9) | I3: (8) | J3: (7) | K3: (6) | L3: (5) | M3: (4) | N3: (3) | O3: (2) | P3: (1) | Q3: No Evidence (0) | R3: Score (0-12) | S3: Avg. Score | T3: Comments
A4: Front Matter | B4: =Data!A5 -> i | C4: =Data!B5 -> Cover Page and Table of Contents | D4: =Data!C5 -> Professional representation of the project. Gate Report sections listed (e.g., body, references, and appendices) with correct page numbers. Updated and/or impacted sections highlighted in red. | E4: x | R4: =IF(E4="x",12,IF(F4="x",11,IF(G4="x",10,IF(H4="x",9,IF(I4="x",8,IF(J4="x",7,IF(K4="x",6,IF(L4="x",5,IF(M4="x",4,IF(N4="x",3,IF(O4="x",2,IF(P4="x",1,IF(Q4="x",0,""))))))))))))) -> 12 | S4: =AVERAGE(R4:R5) -> 12
B5: =Data!A6 -> ii | C5: =Data!B6 -> Executive Summary | D5: =Data!C6 -> Concise summary of the current accomplishments and the future expectations for the next Gate Report. Updated at every Gate Report. | E5: x | R5: =IF(E5="x",12,IF(F5="x",11,IF(G5="x",10,IF(H5="x",9,IF(I5="x",8,IF(J5="x",7,IF(K5="x",6,IF(L5="x",5,IF(M5="x",4,IF(N5="x",3,IF(O5="x",2,IF(P5="x",1,IF(Q5="x",0,""))))))))))))) -> 12
A6: Project Definition | B6: =Data!A23 -> 1.1 | C6: =Data!B23 -> Problem Description | D6: =Data!C23 -> Includes context to the problem, reason for the problem, need for this project, defines who is impacted by the problem (customer / market) and how. | E6: x | R6: =IF(E6="x",12,IF(F6="x",11,IF(G6="x",10,IF(H6="x",9,IF(I6="x",8,IF(J6="x",7,IF(K6="x",6,IF(L6="x",5,IF(M6="x",4,IF(N6="x",3,IF(O6="x",2,IF(P6="x",1,IF(Q6="x",0,""))))))))))))) -> 12 | S6: =AVERAGE(R6:R9) -> 12
B7: =Data!A24 -> 1.2 | C7: =Data!B24 -> Problem Statement | D7: =Data!C24 -> Describes the problem in technical detail and Quantifies the impact on the customer/market. Introduce critical performance metrics. Defines the end-user population (e.g., person, environment, or organization). | E7: x | R7: =IF(E7="x",12,IF(F7="x",11,IF(G7="x",10,IF(H7="x",9,IF(I7="x",8,IF(J7="x",7,IF(K7="x",6,IF(L7="x",5,IF(M7="x",4,IF(N7="x",3,IF(O7="x",2,IF(P7="x",1,IF(Q7="x",0,""))))))))))))) -> 12
B8: =Data!A25 -> 1.3 | C8: =Data!B25 -> Scope of Work | D8: =Data!C25 -> Describes the approach to solve this problem, the projected timeline plan, and the assumptions, limitations, and constraints of the project. Describes the services and/or materials to be obtained from the client. | E8: x | R8: =IF(E8="x",12,IF(F8="x",11,IF(G8="x",10,IF(H8="x",9,IF(I8="x",8,IF(J8="x",7,IF(K8="x",6,IF(L8="x",5,IF(M8="x",4,IF(N8="x",3,IF(O8="x",2,IF(P8="x",1,IF(Q8="x",0,""))))))))))))) -> 12
B9: =Data!A26 -> 1.4 | C9: =Data!B26 -> Deliverables | D9: =Data!C26 -> Defines the final product to be delivered at the end of the project. Defines milestones that progress toward the completion of the final product. Deliverables include a completed prototype, all spare parts, design and technical documentation, and test results. The information is specific to the project, and not described as general project deliverables. | E9: x | R9: =IF(E9="x",12,IF(F9="x",11,IF(G9="x",10,IF(H9="x",9,IF(I9="x",8,IF(J9="x",7,IF(K9="x",6,IF(L9="x",5,IF(M9="x",4,IF(N9="x",3,IF(O9="x",2,IF(P9="x",1,IF(Q9="x",0,""))))))))))))) -> 12
A10: Project Research | B10: =Data!A28 -> 2.1 | C10: =Data!B28 -> Review of the Problem Area | D10: =Data!C28 -> Summarizes and synthesizes existing research to support the claims of the problem. Information gathered is technically sound and adequate, e.g., summarizes benchmarked prototypes, patents, research publications, etc. Properly cited work using IEEE style. Includes visual aids (e.g., figures, tables) and technical details to introduce the various claims and approaches published in literature. | E10: x | R10: =IF(E10="x",12,IF(F10="x",11,IF(G10="x",10,IF(H10="x",9,IF(I10="x",8,IF(J10="x",7,IF(K10="x",6,IF(L10="x",5,IF(M10="x",4,IF(N10="x",3,IF(O10="x",2,IF(P10="x",1,IF(Q10="x",0,""))))))))))))) -> 12 | S10: =AVERAGE(R10:R11) -> 12
B11: =Data!A29 -> 2.2 | C11: =Data!B29 -> Review of State-of-the-Art | D11: =Data!C29 -> Introduces relevant products and technologies that exist in research or the market. Introduces appropriate metrics to describe the State-of-Art performance. | E11: x | R11: =IF(E11="x",12,IF(F11="x",11,IF(G11="x",10,IF(H11="x",9,IF(I11="x",8,IF(J11="x",7,IF(K11="x",6,IF(L11="x",5,IF(M11="x",4,IF(N11="x",3,IF(O11="x",2,IF(P11="x",1,IF(Q11="x",0,""))))))))))))) -> 12
A12: Project Development | B12: =Data!A31 -> 3.1 | C12: =Data!B31 -> Requirements Matrix | D12: =Data!C31 -> Translates the client's needs into engineering statements using relevant metrics of performance (one, unambiguous and measurable value). Describes the relationships between these statements. Has received Client approval. | E12: x | R12: =IF(E12="x",12,IF(F12="x",11,IF(G12="x",10,IF(H12="x",9,IF(I12="x",8,IF(J12="x",7,IF(K12="x",6,IF(L12="x",5,IF(M12="x",4,IF(N12="x",3,IF(O12="x",2,IF(P12="x",1,IF(Q12="x",0,""))))))))))))) -> 12 | S12: =AVERAGE(R12:R13) -> 12
B13: =Data!A32 -> 3.2 | C13: =Data!B32 -> Exploratory Concepts | D13: =Data!C32 -> Presents (at least) three exploratory designs that can potentially meet the design requirements. Provides evidence to substantiate the validity of the designs. Points out the strengths and weaknesses of each design. Includes sketches and/or models to demonstrate the completeness of the exploratory designs. | E13: x | R13: =IF(E13="x",12,IF(F13="x",11,IF(G13="x",10,IF(H13="x",9,IF(I13="x",8,IF(J13="x",7,IF(K13="x",6,IF(L13="x",5,IF(M13="x",4,IF(N13="x",3,IF(O13="x",2,IF(P13="x",1,IF(Q13="x",0,""))))))))))))) -> 12
A14: Team Organization | B14: =Data!A35 -> 4.1 | C14: =Data!B35 -> Member Bios, Team Member Roles | D14: =Data!C35 -> Table includes students' image, name, degree(s), and assigned role(s). | E14: x | R14: =IF(E14="x",12,IF(F14="x",11,IF(G14="x",10,IF(H14="x",9,IF(I14="x",8,IF(J14="x",7,IF(K14="x",6,IF(L14="x",5,IF(M14="x",4,IF(N14="x",3,IF(O14="x",2,IF(P14="x",1,IF(Q14="x",0,""))))))))))))) -> 12 | S14: =AVERAGE(R14:R15) -> 12
B15: =Data!A36 -> 4.2 | C15: =Data!B36 -> Team Charter | D15: =Data!C36 -> Expectations listed for each team member, faculty mentor and customer mentor. | E15: x | R15: =IF(E15="x",12,IF(F15="x",11,IF(G15="x",10,IF(H15="x",9,IF(I15="x",8,IF(J15="x",7,IF(K15="x",6,IF(L15="x",5,IF(M15="x",4,IF(N15="x",3,IF(O15="x",2,IF(P15="x",1,IF(Q15="x",0,""))))))))))))) -> 12
A16: Project Management | B16: =Data!A65 -> 10.1 | C16: =Data!B65 -> Project Schedule | D16: =Data!C65 -> Task descriptions contain an acceptable level of detail. Task predecessor links properly used with no open-ended tasks. Task progress bar properly used to indicate % completion status of active tasks. All tasks set to Auto-Schedule mode. All Resource Names added. Milestones identified and properly linked. All task flow in a chronological order. | E16: x | R16: =IF(E16="x",12,IF(F16="x",11,IF(G16="x",10,IF(H16="x",9,IF(I16="x",8,IF(J16="x",7,IF(K16="x",6,IF(L16="x",5,IF(M16="x",4,IF(N16="x",3,IF(O16="x",2,IF(P16="x",1,IF(Q16="x",0,""))))))))))))) -> 12 | S16: =AVERAGE(R16:R18) -> 12
B17: =Data!A66 -> 10.2 | C17: =Data!B66 -> Gantt Charts & Critical Path | D17: =Data!C66&"1" -> Gantt Chart(s): Properly formatted to clearly define project status details and all information in the Gantt Charts is aligned with the Gate requirements. Task level information clearly indicates an appropriate level of detail. Chart types are properly created as defined in the Project Schedule Guidelines. Critical Path: MS Project able to calculate critical path based on existing tasks and predecessor structure. Clearly defined and shown using the Level 3 chart format. Gantt Charts content should be To gate 1 | E17: x | R17: =IF(E17="x",12,IF(F17="x",11,IF(G17="x",10,IF(H17="x",9,IF(I17="x",8,IF(J17="x",7,IF(K17="x",6,IF(L17="x",5,IF(M17="x",4,IF(N17="x",3,IF(O17="x",2,IF(P17="x",1,IF(Q17="x",0,""))))))))))))) -> 12
B18: =Data!A67 -> 10.3 | C18: =Data!B67 -> MS Teams File Documentation | D18: =Data!C67 -> Certification table filled in and signed by the responsible team member. | E18: x | R18: =IF(E18="x",12,IF(F18="x",11,IF(G18="x",10,IF(H18="x",9,IF(I18="x",8,IF(J18="x",7,IF(K18="x",6,IF(L18="x",5,IF(M18="x",4,IF(N18="x",3,IF(O18="x",2,IF(P18="x",1,IF(Q18="x",0,""))))))))))))) -> 12
A19: Report Quality | C19: =Data!B7 -> Formatting and References | D19: =Data!C7 -> Uses IEEE format to develop the Title Page, Table of Contents, Appendix, and Work Cited sections of this report. | E19: x | R19: =IF(E19="x",12,IF(F19="x",11,IF(G19="x",10,IF(H19="x",9,IF(I19="x",8,IF(J19="x",7,IF(K19="x",6,IF(L19="x",5,IF(M19="x",4,IF(N19="x",3,IF(O19="x",2,IF(P19="x",1,IF(Q19="x",0,""))))))))))))) -> 12 | S19: =AVERAGE(R19:R21) -> 12
C20: =Data!B8 -> Text | D20: =Data!C8 -> Free of spelling and grammatical errors, text flows with contiguous threads, consistent format, use of 3rd person perspective, non-repeating ideas or information. | E20: x | R20: =IF(E20="x",12,IF(F20="x",11,IF(G20="x",10,IF(H20="x",9,IF(I20="x",8,IF(J20="x",7,IF(K20="x",6,IF(L20="x",5,IF(M20="x",4,IF(N20="x",3,IF(O20="x",2,IF(P20="x",1,IF(Q20="x",0,""))))))))))))) -> 12
C21: =Data!B9 -> Visual Aids | D21: =Data!C9 -> Visual aids (all figures including hand sketches, photos, charts, etc. and tables) are clear and readable and of professional quality. Graphic aspects labeled and linked to text to transmit critical information, units/scaling clear. Proper IEEE style utilized. | E21: X | R21: =IF(E21="x",12,IF(F21="x",11,IF(G21="x",10,IF(H21="x",9,IF(I21="x",8,IF(J21="x",7,IF(K21="x",6,IF(L21="x",5,IF(M21="x",4,IF(N21="x",3,IF(O21="x",2,IF(P21="x",1,IF(Q21="x",0,""))))))))))))) -> 12
B22: =Data!A75 -> A1 | C22: =Data!B75 -> Communication Plan | D22: =Data!C75 -> Communication Plan template fully filled in. Communication channels appear appropriate for the current team progress and level of communication occurring. Clearly defined descriptions of all portions of the plan. | E22: X | R22: =IF(E22="x",12,IF(F22="x",11,IF(G22="x",10,IF(H22="x",9,IF(I22="x",8,IF(J22="x",7,IF(K22="x",6,IF(L22="x",5,IF(M22="x",4,IF(N22="x",3,IF(O22="x",2,IF(P22="x",1,IF(Q22="x",0,""))))))))))))) -> 12 | S22: =AVERAGE(R22:R23) -> 12
B23: =Data!A76 -> A2 | C23: =Data!B76 -> Team Member Bios | D23: =Data!C76 -> Describes each member's motivation to participate and succeed in this project. | E23: x | R23: =IF(E23="x",12,IF(F23="x",11,IF(G23="x",10,IF(H23="x",9,IF(I23="x",8,IF(J23="x",7,IF(K23="x",6,IF(L23="x",5,IF(M23="x",4,IF(N23="x",3,IF(O23="x",2,IF(P23="x",1,IF(Q23="x",0,""))))))))))))) -> 12
A24: Comments | R24: Total Points | S24: =SUM(S4:S23) -> 96
R25: Points Available | S25: 96
R26: Grade % | S26: =S24/S25 -> 1

Sheet G1.5P
A2: Gate 1.5 Project Status Report - Oral Presentation Rubric
A3: Category | B3: Report Sec. # | C3: Title | D3: Requirements | E3: Meets Expectations (12) | F3: (11) | G3: (10) | H3: (9) | I3: (8) | J3: (7) | K3: (6) | L3: (5) | M3: (4) | N3: (3) | O3: (2) | P3: (1) | Q3: No Evidence (0) | R3: Score (0-12) | S3: Avg. Score
A4: Overall Presentation | C4: =Data!B10 -> Introduction | D4: =Data!C10 -> Presentation Title (closely matches project name), Outline (follows Rubric), Team Members (photo, name, academic major, team role) Concise overview of project. | E4: x | R4: =IF(E4="x",12,IF(F4="x",11,IF(G4="x",10,IF(H4="x",9,IF(I4="x",8,IF(J4="x",7,IF(K4="x",6,IF(L4="x",5,IF(M4="x",4,IF(N4="x",3,IF(O4="x",2,IF(P4="x",1,IF(Q4="x",0,""))))))))))))) -> 12 | S4: =AVERAGE(R4:R7) -> 12
C5: =Data!B12 -> Audio / Visual Quality of Presentation | D5: =Data!C12 -> Figures and tables in engineering format, free of spelling and grammatical errors, data presented is well-organized and defined in tabular or graphical form. Annotations are used to describe key points of photos and graphics. All slides are labeled with page numbers and consistent formatting between slides. Audio quality good no background noise or distractions. | E5: x | R5: =IF(E5="x",12,IF(F5="x",11,IF(G5="x",10,IF(H5="x",9,IF(I5="x",8,IF(J5="x",7,IF(K5="x",6,IF(L5="x",5,IF(M5="x",4,IF(N5="x",3,IF(O5="x",2,IF(P5="x",1,IF(Q5="x",0,""))))))))))))) -> 12
C6: =Data!B13 -> References | D6: =Data!C13 -> References (in-text and bibliography) properly cited in IEEE style. Proper use of the Zotero citation management tool | E6: x | R6: =IF(E6="x",12,IF(F6="x",11,IF(G6="x",10,IF(H6="x",9,IF(I6="x",8,IF(J6="x",7,IF(K6="x",6,IF(L6="x",5,IF(M6="x",4,IF(N6="x",3,IF(O6="x",2,IF(P6="x",1,IF(Q6="x",0,""))))))))))))) -> 12
C7: =Data!B11 -> Oral Presentation Skill | D7: =Data!C11 -> Clear enunciation when discussing engineering design. All members are participating. Smooth transitions between topics and presenters. | E7: x | R7: =IF(E7="x",12,IF(F7="x",11,IF(G7="x",10,IF(H7="x",9,IF(I7="x",8,IF(J7="x",7,IF(K7="x",6,IF(L7="x",5,IF(M7="x",4,IF(N7="x",3,IF(O7="x",2,IF(P7="x",1,IF(Q7="x",0,""))))))))))))) -> 12
A8: Comments
A9: Project Definition | B9: =Data!A23 -> 1.1 | C9: =Data!B23 -> Problem Description | D9: =Data!C23 -> Includes context to the problem, reason for the problem, need for this project, defines who is impacted by the problem (customer / market) and how. | E9: x | R9: =IF(E9="x",12,IF(F9="x",11,IF(G9="x",10,IF(H9="x",9,IF(I9="x",8,IF(J9="x",7,IF(K9="x",6,IF(L9="x",5,IF(M9="x",4,IF(N9="x",3,IF(O9="x",2,IF(P9="x",1,IF(Q9="x",0,""))))))))))))) -> 12 | S9: =AVERAGE(R9:R12) -> 12
B10: =Data!A24 -> 1.2 | C10: =Data!B24 -> Problem Statement | D10: =Data!C24 -> Describes the problem in technical detail and Quantifies the impact on the customer/market. Introduce critical performance metrics. Defines the end-user population (e.g., person, environment, or organization). | E10: x | R10: =IF(E10="x",12,IF(F10="x",11,IF(G10="x",10,IF(H10="x",9,IF(I10="x",8,IF(J10="x",7,IF(K10="x",6,IF(L10="x",5,IF(M10="x",4,IF(N10="x",3,IF(O10="x",2,IF(P10="x",1,IF(Q10="x",0,""))))))))))))) -> 12
B11: =Data!A25 -> 1.3 | C11: =Data!B25 -> Scope of Work | D11: =Data!C25 -> Describes the approach to solve this problem, the projected timeline plan, and the assumptions, limitations, and constraints of the project. Describes the services and/or materials to be obtained from the client. | E11: x | R11: =IF(E11="x",12,IF(F11="x",11,IF(G11="x",10,IF(H11="x",9,IF(I11="x",8,IF(J11="x",7,IF(K11="x",6,IF(L11="x",5,IF(M11="x",4,IF(N11="x",3,IF(O11="x",2,IF(P11="x",1,IF(Q11="x",0,""))))))))))))) -> 12
B12: =Data!A26 -> 1.4 | C12: =Data!B26 -> Deliverables | D12: =Data!C26 -> Defines the final product to be delivered at the end of the project. Defines milestones that progress toward the completion of the final product. Deliverables include a completed prototype, all spare parts, design and technical documentation, and test results. The information is specific to the project, and not described as general project deliverables. | E12: x | R12: =IF(E12="x",12,IF(F12="x",11,IF(G12="x",10,IF(H12="x",9,IF(I12="x",8,IF(J12="x",7,IF(K12="x",6,IF(L12="x",5,IF(M12="x",4,IF(N12="x",3,IF(O12="x",2,IF(P12="x",1,IF(Q12="x",0,""))))))))))))) -> 12
A13: Comments
A14: Project Research | B14: =Data!A28 -> 2.1 | C14: =Data!B28 -> Review of the Problem Area | D14: =Data!C28 -> Summarizes and synthesizes existing research to support the claims of the problem. Information gathered is technically sound and adequate, e.g., summarizes benchmarked prototypes, patents, research publications, etc. Properly cited work using IEEE style. Includes visual aids (e.g., figures, tables) and technical details to introduce the various claims and approaches published in literature. | E14: x | R14: =IF(E14="x",12,IF(F14="x",11,IF(G14="x",10,IF(H14="x",9,IF(I14="x",8,IF(J14="x",7,IF(K14="x",6,IF(L14="x",5,IF(M14="x",4,IF(N14="x",3,IF(O14="x",2,IF(P14="x",1,IF(Q14="x",0,""))))))))))))) -> 12 | S14: =AVERAGE(R14:R15) -> 12
B15: =Data!A29 -> 2.2 | C15: =Data!B29 -> Review of State-of-the-Art | D15: =Data!C29 -> Introduces relevant products and technologies that exist in research or the market. Introduces appropriate metrics to describe the State-of-Art performance. | E15: x | R15: =IF(E15="x",12,IF(F15="x",11,IF(G15="x",10,IF(H15="x",9,IF(I15="x",8,IF(J15="x",7,IF(K15="x",6,IF(L15="x",5,IF(M15="x",4,IF(N15="x",3,IF(O15="x",2,IF(P15="x",1,IF(Q15="x",0,""))))))))))))) -> 12
A16: Comments
A17: Project Development | B17: =Data!A31 -> 3.1 | C17: =Data!B31 -> Requirements Matrix | D17: =Data!C31 -> Translates the client's needs into engineering statements using relevant metrics of performance (one, unambiguous and measurable value). Describes the relationships between these statements. Has received Client approval. | E17: x | R17: =IF(E17="x",12,IF(F17="x",11,IF(G17="x",10,IF(H17="x",9,IF(I17="x",8,IF(J17="x",7,IF(K17="x",6,IF(L17="x",5,IF(M17="x",4,IF(N17="x",3,IF(O17="x",2,IF(P17="x",1,IF(Q17="x",0,""))))))))))))) -> 12 | S17: =AVERAGE(R17:R18) -> 12
B18: =Data!A32 -> 3.2 | C18: =Data!B32 -> Exploratory Concepts | D18: =Data!C32 -> Presents (at least) three exploratory designs that can potentially meet the design requirements. Provides evidence to substantiate the validity of the designs. Points out the strengths and weaknesses of each design. Includes sketches and/or models to demonstrate the completeness of the exploratory designs. | E18: x | R18: =IF(E18="x",12,IF(F18="x",11,IF(G18="x",10,IF(H18="x",9,IF(I18="x",8,IF(J18="x",7,IF(K18="x",6,IF(L18="x",5,IF(M18="x",4,IF(N18="x",3,IF(O18="x",2,IF(P18="x",1,IF(Q18="x",0,""))))))))))))) -> 12
A19: Comments
A20: Team Organization | B20: =Data!A35 -> 4.1 | C20: =Data!B35 -> Member Bios, Team Member Roles | D20: =Data!C35 -> Table includes students' image, name, degree(s), and assigned role(s). | E20: x | R20: =IF(E20="x",12,IF(F20="x",11,IF(G20="x",10,IF(H20="x",9,IF(I20="x",8,IF(J20="x",7,IF(K20="x",6,IF(L20="x",5,IF(M20="x",4,IF(N20="x",3,IF(O20="x",2,IF(P20="x",1,IF(Q20="x",0,""))))))))))))) -> 12 | S20: =AVERAGE(R20:R21) -> 12
B21: =Data!A36 -> 4.2 | C21: =Data!B36 -> Team Charter | D21: =Data!C36 -> Expectations listed for each team member, faculty mentor and customer mentor. | E21: x | R21: =IF(E21="x",12,IF(F21="x",11,IF(G21="x",10,IF(H21="x",9,IF(I21="x",8,IF(J21="x",7,IF(K21="x",6,IF(L21="x",5,IF(M21="x",4,IF(N21="x",3,IF(O21="x",2,IF(P21="x",1,IF(Q21="x",0,""))))))))))))) -> 12
A22: Comments
A23: Design Development | B23: =Data!A39 -> 5.2 | C23: =Data!B39 -> Conceptual Design | D23: =Data!C39 -> Presents (at least) three detailed conceptual designs that can meet the design requirements. Provides evidence to substantiate the validity of the designs. Points out strengths and weaknesses of each. Includes sketches and/or models to demonstrate the completeness of the designs. | E23: X | R23: =IF(E23="x",12,IF(F23="x",11,IF(G23="x",10,IF(H23="x",9,IF(I23="x",8,IF(J23="x",7,IF(K23="x",6,IF(L23="x",5,IF(M23="x",4,IF(N23="x",3,IF(O23="x",2,IF(P23="x",1,IF(Q23="x",0,""))))))))))))) -> 12 | S23: =R23 -> 12
B24: =Data!A40 -> 5.3 | C24: =Data!B40 -> Down Selection Process | D24: =Data!C40 -> Discusses the results of the Down Selection process, includes the criteria and weighting factors for each criterion. Defines the final selection and explains why. | E24: x | R24: =IF(E24="x",12,IF(F24="x",11,IF(G24="x",10,IF(H24="x",9,IF(I24="x",8,IF(J24="x",7,IF(K24="x",6,IF(L24="x",5,IF(M24="x",4,IF(N24="x",3,IF(O24="x",2,IF(P24="x",1,IF(Q24="x",0,""))))))))))))) -> 12 | S24: =AVERAGE(R24:R25) -> 12
B25: =Data!A44 -> 5.7 | C25: =Data!B44 -> Critical Issues & Risk Mitigation | D25: =Data!C44 -> Explains critical issues that have arisen. Translates critical issues into sequential action items. Explains the affect(s) on the critical path and schedule. | E25: x | R25: =IF(E25="x",12,IF(F25="x",11,IF(G25="x",10,IF(H25="x",9,IF(I25="x",8,IF(J25="x",7,IF(K25="x",6,IF(L25="x",5,IF(M25="x",4,IF(N25="x",3,IF(O25="x",2,IF(P25="x",1,IF(Q25="x",0,""))))))))))))) -> 12
A26: Comments
A27: Project Management | B27: =Data!A65 -> 10.1 | C27: =Data!B65 -> Project Schedule | D27: =Data!C65 -> Task descriptions contain an acceptable level of detail. Task predecessor links properly used with no open-ended tasks. Task progress bar properly used to indicate % completion status of active tasks. All tasks set to Auto-Schedule mode. All Resource Names added. Milestones identified and properly linked. All task flow in a chronological order. | E27: x | R27: =IF(E27="x",12,IF(F27="x",11,IF(G27="x",10,IF(H27="x",9,IF(I27="x",8,IF(J27="x",7,IF(K27="x",6,IF(L27="x",5,IF(M27="x",4,IF(N27="x",3,IF(O27="x",2,IF(P27="x",1,IF(Q27="x",0,""))))))))))))) -> 12 | S27: =AVERAGE(R27:R28) -> 12
B28: =Data!A66 -> 10.2 | C28: =Data!B66 -> Gantt Charts & Critical Path | D28: =Data!C66&" 1.5 & Gate 2 Tasks." -> Gantt Chart(s): Properly formatted to clearly define project status details and all information in the Gantt Charts is aligned with the Gate requirements. Task level information clearly indicates an appropriate level of detail. Chart types are properly created as defined in the Project Schedule Guidelines. Critical Path: MS Project able to calculate critical path based on existing tasks and predecessor structure. Clearly defined and shown using the Level 3 chart format. Gantt Charts content should be To gate 1.5 & Gate 2 Tasks. | E28: x | R28: =IF(E28="x",12,IF(F28="x",11,IF(G28="x",10,IF(H28="x",9,IF(I28="x",8,IF(J28="x",7,IF(K28="x",6,IF(L28="x",5,IF(M28="x",4,IF(N28="x",3,IF(O28="x",2,IF(P28="x",1,IF(Q28="x",0,""))))))))))))) -> 12
A29: Comments | R29: Total Points | S29: =SUM(S4:S28) -> 96
R30: Points Available | S30: 96
R31: Grade % | S31: =S29/S30 -> 1

Sheet G2R
A2: Gate 2 Technical Report Rubric
A3: Category | B3: Report Sec.# | C3: Title | D3: Requirements (Additional information provided in Guidelines_Report.doc) | E3: Meets Expectations (12) | F3: (11) | G3: (10) | H3: (9) | I3: (8) | J3: (7) | K3: (6) | L3: (5) | M3: (4) | N3: (3) | O3: (2) | P3: (1) | Q3: No Evidence (0) | R3: Score (0-12) | S3: Weight | T3: Avg. Score
A4: Updated Sections based on feedback from Previous Gate(s) | B4: =Data!A6 -> ii | C4: =Data!B6 -> Executive Summary | D4: Updated for Gate 2 and based upon feedback from previous Gate Report. | E4: x | R4: =IF(E4="x",12,IF(F4="x",11,IF(G4="x",10,IF(H4="x",9,IF(I4="x",8,IF(J4="x",7,IF(K4="x",6,IF(L4="x",5,IF(M4="x",4,IF(N4="x",3,IF(O4="x",2,IF(P4="x",1,IF(Q4="x",0,""))))))))))))) -> 12 | S4: 1 | T4: =AVERAGE(R4:R9)*S4 -> 12
B5: =Data!A25 -> 1.3 | C5: =Data!B25 -> Scope of Work | E5: x | R5: =IF(E5="x",12,IF(F5="x",11,IF(G5="x",10,IF(H5="x",9,IF(I5="x",8,IF(J5="x",7,IF(K5="x",6,IF(L5="x",5,IF(M5="x",4,IF(N5="x",3,IF(O5="x",2,IF(P5="x",1,IF(Q5="x",0,""))))))))))))) -> 12
B6: =Data!A26 -> 1.4 | C6: =Data!B26 -> Deliverables | E6: x | R6: =IF(E6="x",12,IF(F6="x",11,IF(G6="x",10,IF(H6="x",9,IF(I6="x",8,IF(J6="x",7,IF(K6="x",6,IF(L6="x",5,IF(M6="x",4,IF(N6="x",3,IF(O6="x",2,IF(P6="x",1,IF(Q6="x",0,""))))))))))))) -> 12
B7: =Data!A31 -> 3.1 | C7: =Data!B31 -> Requirements Matrix | E7: x | R7: =IF(E7="x",12,IF(F7="x",11,IF(G7="x",10,IF(H7="x",9,IF(I7="x",8,IF(J7="x",7,IF(K7="x",6,IF(L7="x",5,IF(M7="x",4,IF(N7="x",3,IF(O7="x",2,IF(P7="x",1,IF(Q7="x",0,""))))))))))))) -> 12
B8: =Data!A32 -> 3.2 | C8: =Data!B32 -> Exploratory Concepts | E8: x | R8: =IF(E8="x",12,IF(F8="x",11,IF(G8="x",10,IF(H8="x",9,IF(I8="x",8,IF(J8="x",7,IF(K8="x",6,IF(L8="x",5,IF(M8="x",4,IF(N8="x",3,IF(O8="x",2,IF(P8="x",1,IF(Q8="x",0,""))))))))))))) -> 12
B9: =Data!A67 -> 10.3 | C9: =Data!B67 -> MS Teams File Documentation | E9: x | R9: =IF(E9="x",12,IF(F9="x",11,IF(G9="x",10,IF(H9="x",9,IF(I9="x",8,IF(J9="x",7,IF(K9="x",6,IF(L9="x",5,IF(M9="x",4,IF(N9="x",3,IF(O9="x",2,IF(P9="x",1,IF(Q9="x",0,""))))))))))))) -> 12
A10: Project Research | B10: =Data!A28 -> 2.1 | C10: =Data!B28 -> Review of the Problem Area | D10: =Data!C28 -> Summarizes and synthesizes existing research to support the claims of the problem. Information gathered is technically sound and adequate, e.g., summarizes benchmarked prototypes, patents, research publications, etc. Properly cited work using IEEE style. Includes visual aids (e.g., figures, tables) and technical details to introduce the various claims and approaches published in literature. | E10: x | R10: =IF(E10="x",12,IF(F10="x",11,IF(G10="x",10,IF(H10="x",9,IF(I10="x",8,IF(J10="x",7,IF(K10="x",6,IF(L10="x",5,IF(M10="x",4,IF(N10="x",3,IF(O10="x",2,IF(P10="x",1,IF(Q10="x",0,""))))))))))))) -> 12 | S10: 1 | T10: =AVERAGE(R10:R11)*S10 -> 12
B11: =Data!A29 -> 2.2 | C11: =Data!B29 -> Review of State-of-the-Art | D11: =Data!C29 -> Introduces relevant products and technologies that exist in research or the market. Introduces appropriate metrics to describe the State-of-Art performance. | E11: x | R11: =IF(E11="x",12,IF(F11="x",11,IF(G11="x",10,IF(H11="x",9,IF(I11="x",8,IF(J11="x",7,IF(K11="x",6,IF(L11="x",5,IF(M11="x",4,IF(N11="x",3,IF(O11="x",2,IF(P11="x",1,IF(Q11="x",0,""))))))))))))) -> 12
A12: Project Development | B12: =Data!A31 -> 3.1 | C12: =Data!B31 -> Requirements Matrix | D12: =Data!C31 -> Translates the client's needs into engineering statements using relevant metrics of performance (one, unambiguous and measurable value). Describes the relationships between these statements. Has received Client approval. | E12: x | R12: =IF(E12="x",12,IF(F12="x",11,IF(G12="x",10,IF(H12="x",9,IF(I12="x",8,IF(J12="x",7,IF(K12="x",6,IF(L12="x",5,IF(M12="x",4,IF(N12="x",3,IF(O12="x",2,IF(P12="x",1,IF(Q12="x",0,""))))))))))))) -> 12 | S12: 1.5 | T12: =AVERAGE(R12:R14)*S12 -> 18
B13: =Data!A32 -> 3.2 | C13: =Data!B32 -> Exploratory Concepts | D13: =Data!C32 -> Presents (at least) three exploratory designs that can potentially meet the design requirements. Provides evidence to substantiate the validity of the designs. Points out the strengths and weaknesses of each design. Includes sketches and/or models to demonstrate the completeness of the exploratory designs. | E13: x | R13: =IF(E13="x",12,IF(F13="x",11,IF(G13="x",10,IF(H13="x",9,IF(I13="x",8,IF(J13="x",7,IF(K13="x",6,IF(L13="x",5,IF(M13="x",4,IF(N13="x",3,IF(O13="x",2,IF(P13="x",1,IF(Q13="x",0,""))))))))))))) -> 12
B14: =Data!A33 -> 3.3 | C14: =Data!B33 -> Resource Requirements | D14: =Data!C33 -> Expected resource needs to support the project are clearly defined. Status and timeline of any on-going Investigations into resource availabilities is well defined. | E14: x | R14: =IF(E14="x",12,IF(F14="x",11,IF(G14="x",10,IF(H14="x",9,IF(I14="x",8,IF(J14="x",7,IF(K14="x",6,IF(L14="x",5,IF(M14="x",4,IF(N14="x",3,IF(O14="x",2,IF(P14="x",1,IF(Q14="x",0,""))))))))))))) -> 12
A15: Design Development | B15: =Data!A38 -> 5.1 | C15: =Data!B38 -> System Decomposition | D15: =Data!C38 -> Decompose the complexity of the system/problem by describing its constituent components. Break down the complex system/problem into smaller, more manageable parts by building a hierarchical representation of critical subsystems. Depending on the system, you may consider developing a functional decomposition, assembly decomposition, or service-based decomposition. | E15: x | R15: =IF(E15="x",12,IF(F15="x",11,IF(G15="x",10,IF(H15="x",9,IF(I15="x",8,IF(J15="x",7,IF(K15="x",6,IF(L15="x",5,IF(M15="x",4,IF(N15="x",3,IF(O15="x",2,IF(P15="x",1,IF(Q15="x",0,""))))))))))))) -> 12 | S15: 1.5 | T15: =AVERAGE(R15:R17)*S15 -> 18
B16: =Data!A39 -> 5.2 | C16: =Data!B39 -> Conceptual Design | D16: =Data!C39 -> Presents (at least) three detailed conceptual designs that can meet the design requirements. Provides evidence to substantiate the validity of the designs. Points out strengths and weaknesses of each. Includes sketches and/or models to demonstrate the completeness of the designs. | E16: x | R16: =IF(E16="x",12,IF(F16="x",11,IF(G16="x",10,IF(H16="x",9,IF(I16="x",8,IF(J16="x",7,IF(K16="x",6,IF(L16="x",5,IF(M16="x",4,IF(N16="x",3,IF(O16="x",2,IF(P16="x",1,IF(Q16="x",0,""))))))))))))) -> 12
B17: =Data!A40 -> 5.3 | C17: =Data!B40 -> Down Selection Process | D17: =Data!C40 -> Discusses the results of the Down Selection process, includes the criteria and weighting factors for each criterion. Defines the final selection and explains why. | E17: x | R17: =IF(E17="x",12,IF(F17="x",11,IF(G17="x",10,IF(H17="x",9,IF(I17="x",8,IF(J17="x",7,IF(K17="x",6,IF(L17="x",5,IF(M17="x",4,IF(N17="x",3,IF(O17="x",2,IF(P17="x",1,IF(Q17="x",0,""))))))))))))) -> 12
B18: =Data!A42 -> 5.5 | C18: =Data!B42 -> Design Calculations & Analysis Results | D18: =Data!C42 -> Provide and describe the analytical models used to support the design. (FEA, Electrical simulations, Mechanical analysis) Provide and describe the experiments and measurements that support the design. | E18: x | R18: =IF(E18="x",12,IF(F18="x",11,IF(G18="x",10,IF(H18="x",9,IF(I18="x",8,IF(J18="x",7,IF(K18="x",6,IF(L18="x",5,IF(M18="x",4,IF(N18="x",3,IF(O18="x",2,IF(P18="x",1,IF(Q18="x",0,""))))))))))))) -> 12 | S18: 1 | T18: =AVERAGE(R18:R20)*S18 -> 12
B19: =Data!A43 -> 5.6 | C19: =Data!B43 -> Mathematical Modeling (Lit review) | D19: =Data!C43 -> Define all analytical approaches to be used to support confirmation that your system design will meet the client requirements. | E19: x | R19: =IF(E19="x",12,IF(F19="x",11,IF(G19="x",10,IF(H19="x",9,IF(I19="x",8,IF(J19="x",7,IF(K19="x",6,IF(L19="x",5,IF(M19="x",4,IF(N19="x",3,IF(O19="x",2,IF(P19="x",1,IF(Q19="x",0,""))))))))))))) -> 12
B20: =Data!A44 -> 5.7 | C20: =Data!B44 -> Critical Issues & Risk Mitigation | D20: =Data!C44 -> Explains critical issues that have arisen. Translates critical issues into sequential action items. Explains the affect(s) on the critical path and schedule. | E20: x | R20: =IF(E20="x",12,IF(F20="x",11,IF(G20="x",10,IF(H20="x",9,IF(I20="x",8,IF(J20="x",7,IF(K20="x",6,IF(L20="x",5,IF(M20="x",4,IF(N20="x",3,IF(O20="x",2,IF(P20="x",1,IF(Q20="x",0,""))))))))))))) -> 12
A21: Project Management | B21: =Data!A65 -> 10.1 | C21: =Data!B65 -> Project Schedule | D21: =Data!C65 -> Task descriptions contain an acceptable level of detail. Task predecessor links properly used with no open-ended tasks. Task progress bar properly used to indicate % completion status of active tasks. All tasks set to Auto-Schedule mode. All Resource Names added. Milestones identified and properly linked. All task flow in a chronological order. | E21: x | R21: =IF(E21="x",12,IF(F21="x",11,IF(G21="x",10,IF(H21="x",9,IF(I21="x",8,IF(J21="x",7,IF(K21="x",6,IF(L21="x",5,IF(M21="x",4,IF(N21="x",3,IF(O21="x",2,IF(P21="x",1,IF(Q21="x",0,""))))))))))))) -> 12 | S21: 0.75 | T21: =AVERAGE(R21:R22)*S21 -> 9
B22: =Data!A66 -> 10.2 | C22: =Data!B66 -> Gantt Charts & Critical Path | D22: =Data!C66&" 3 Tasks." -> Gantt Chart(s): Properly formatted to clearly define project status details and all information in the Gantt Charts is aligned with the Gate requirements. Task level information clearly indicates an appropriate level of detail. Chart types are properly created as defined in the Project Schedule Guidelines. Critical Path: MS Project able to calculate critical path based on existing tasks and predecessor structure. Clearly defined and shown using the Level 3 chart format. Gantt Charts content should be To gate 3 Tasks. | E22: x | R22: =IF(E22="x",12,IF(F22="x",11,IF(G22="x",10,IF(H22="x",9,IF(I22="x",8,IF(J22="x",7,IF(K22="x",6,IF(L22="x",5,IF(M22="x",4,IF(N22="x",3,IF(O22="x",2,IF(P22="x",1,IF(Q22="x",0,""))))))))))))) -> 12
A23: Report Quality | C23: =Data!B7 -> Formatting and References | D23: =Data!C7 -> Uses IEEE format to develop the Title Page, Table of Contents, Appendix, and Work Cited sections of this report. | E23: x | R23: =IF(E23="x",12,IF(F23="x",11,IF(G23="x",10,IF(H23="x",9,IF(I23="x",8,IF(J23="x",7,IF(K23="x",6,IF(L23="x",5,IF(M23="x",4,IF(N23="x",3,IF(O23="x",2,IF(P23="x",1,IF(Q23="x",0,""))))))))))))) -> 12 | S23: 1 | T23: =AVERAGE(R23:R25)*S23 -> 12
C24: =Data!B8 -> Text | D24: =Data!C8 -> Free of spelling and grammatical errors, text flows with contiguous threads, consistent format, use of 3rd person perspective, non-repeating ideas or information. | E24: x | R24: =IF(E24="x",12,IF(F24="x",11,IF(G24="x",10,IF(H24="x",9,IF(I24="x",8,IF(J24="x",7,IF(K24="x",6,IF(L24="x",5,IF(M24="x",4,IF(N24="x",3,IF(O24="x",2,IF(P24="x",1,IF(Q24="x",0,""))))))))))))) -> 12
C25: =Data!B9 -> Visual Aids | D25: =Data!C9 -> Visual aids (all figures including hand sketches, photos, charts, etc. and tables) are clear and readable and of professional quality. Graphic aspects labeled and linked to text to transmit critical information, units/scaling clear. Proper IEEE style utilized. | E25: x | R25: =IF(E25="x",12,IF(F25="x",11,IF(G25="x",10,IF(H25="x",9,IF(I25="x",8,IF(J25="x",7,IF(K25="x",6,IF(L25="x",5,IF(M25="x",4,IF(N25="x",3,IF(O25="x",2,IF(P25="x",1,IF(Q25="x",0,""))))))))))))) -> 12
B26: =Data!A77 -> A3 | C26: =Data!B77 -> Down Selection Process | D26: =Data!C77 -> Copy of calculation results for each down selection analysis completed. | E26: x | R26: =IF(E26="x",12,IF(F26="x",11,IF(G26="x",10,IF(H26="x",9,IF(I26="x",8,IF(J26="x",7,IF(K26="x",6,IF(L26="x",5,IF(M26="x",4,IF(N26="x",3,IF(O26="x",2,IF(P26="x",1,IF(Q26="x",0,""))))))))))))) -> 12 | S26: 0.25 | T26: =AVERAGE(R26:R27)*S26 -> 3
B27: =Data!A78 -> A4 | C27: =Data!B78 -> Team Meeting Notes | D27: =Data!C78 -> Contains invitees, attendees, agenda, meeting notes, and task assignment with team member responsibilities clearly labeled. | E27: x | R27: =IF(E27="x",12,IF(F27="x",11,IF(G27="x",10,IF(H27="x",9,IF(I27="x",8,IF(J27="x",7,IF(K27="x",6,IF(L27="x",5,IF(M27="x",4,IF(N27="x",3,IF(O27="x",2,IF(P27="x",1,IF(Q27="x",0,""))))))))))))) -> 12
A28: Comments | R28: Total Points | T28: =SUM(T4:T27) -> 96
R29: Points Available | T29: 96
R30: Grade % | T30: =T28/T29 -> 1

Sheet G2.5P
A2: Gate 2.5 Project Status Report - Oral Presentation Rubric
A3: Category | B3: Report Sec. # | C3: Title | D3: Requirements | E3: Meets Expectations (12) | F3: (11) | G3: (10) | H3: (9) | I3: (8) | J3: (7) | K3: (6) | L3: (5) | M3: (4) | N3: (3) | O3: (2) | P3: (1) | Q3: No Evidence (0) | R3: Score (0-12) | S3: Weight | T3: Avg. Score
A4: Overall Presentation | C4: =Data!B10 -> Introduction | D4: =Data!C10 -> Presentation Title (closely matches project name), Outline (follows Rubric), Team Members (photo, name, academic major, team role) Concise overview of project. | E4: x | R4: =IF(E4="x",12,IF(F4="x",11,IF(G4="x",10,IF(H4="x",9,IF(I4="x",8,IF(J4="x",7,IF(K4="x",6,IF(L4="x",5,IF(M4="x",4,IF(N4="x",3,IF(O4="x",2,IF(P4="x",1,IF(Q4="x",0,""))))))))))))) -> 12 | S4: 1 | T4: =AVERAGE(R4:R7) -> 12
C5: =Data!B12 -> Audio / Visual Quality of Presentation | D5: =Data!C12 -> Figures and tables in engineering format, free of spelling and grammatical errors, data presented is well-organized and defined in tabular or graphical form. Annotations are used to describe key points of photos and graphics. All slides are labeled with page numbers and consistent formatting between slides. Audio quality good no background noise or distractions. | E5: x | R5: =IF(E5="x",12,IF(F5="x",11,IF(G5="x",10,IF(H5="x",9,IF(I5="x",8,IF(J5="x",7,IF(K5="x",6,IF(L5="x",5,IF(M5="x",4,IF(N5="x",3,IF(O5="x",2,IF(P5="x",1,IF(Q5="x",0,""))))))))))))) -> 12
C6: =Data!B13 -> References | D6: =Data!C13 -> References (in-text and bibliography) properly cited in IEEE style. Proper use of the Zotero citation management tool | E6: x | R6: =IF(E6="x",12,IF(F6="x",11,IF(G6="x",10,IF(H6="x",9,IF(I6="x",8,IF(J6="x",7,IF(K6="x",6,IF(L6="x",5,IF(M6="x",4,IF(N6="x",3,IF(O6="x",2,IF(P6="x",1,IF(Q6="x",0,""))))))))))))) -> 12
C7: =Data!B11 -> Oral Presentation Skill | D7: =Data!C11 -> Clear enunciation when discussing engineering design. All members are participating. Smooth transitions between topics and presenters. | E7: x | R7: =IF(E7="x",12,IF(F7="x",11,IF(G7="x",10,IF(H7="x",9,IF(I7="x",8,IF(J7="x",7,IF(K7="x",6,IF(L7="x",5,IF(M7="x",4,IF(N7="x",3,IF(O7="x",2,IF(P7="x",1,IF(Q7="x",0,""))))))))))))) -> 12
A8: Comments
A9: Project introduction | B9: =Data!A23 -> 1.1 | C9: =Data!B23 -> Problem Description | D9: =Data!C23 -> Includes context to the problem, reason for the problem, need for this project, defines who is impacted by the problem (customer / market) and how. | E9: x | R9: =IF(E9="x",12,IF(F9="x",11,IF(G9="x",10,IF(H9="x",9,IF(I9="x",8,IF(J9="x",7,IF(K9="x",6,IF(L9="x",5,IF(M9="x",4,IF(N9="x",3,IF(O9="x",2,IF(P9="x",1,IF(Q9="x",0,""))))))))))))) -> 12 | S9: 1 | T9: =AVERAGE(R9:R12) -> 12
B10: =Data!A24 -> 1.2 | C10: =Data!B24 -> Problem Statement | D10: =Data!C24 -> Describes the problem in technical detail and Quantifies the impact on the customer/market. Introduce critical performance metrics. Defines the end-user population (e.g., person, environment, or organization). | E10: x | R10: =IF(E10="x",12,IF(F10="x",11,IF(G10="x",10,IF(H10="x",9,IF(I10="x",8,IF(J10="x",7,IF(K10="x",6,IF(L10="x",5,IF(M10="x",4,IF(N10="x",3,IF(O10="x",2,IF(P10="x",1,IF(Q10="x",0,""))))))))))))) -> 12
B11: =Data!A25 -> 1.3 | C11: =Data!B25 -> Scope of Work | D11: =Data!C25 -> Describes the approach to solve this problem, the projected timeline plan, and the assumptions, limitations, and constraints of the project. Describes the services and/or materials to be obtained from the client. | E11: x | R11: =IF(E11="x",12,IF(F11="x",11,IF(G11="x",10,IF(H11="x",9,IF(I11="x",8,IF(J11="x",7,IF(K11="x",6,IF(L11="x",5,IF(M11="x",4,IF(N11="x",3,IF(O11="x",2,IF(P11="x",1,IF(Q11="x",0,""))))))))))))) -> 12
B12: =Data!A38 -> 5.1 | C12: =Data!B38 -> System Decomposition | D12: =Data!C38 -> Decompose the complexity of the system/problem by describing its constituent components. Break down the complex system/problem into smaller, more manageable parts by building a hierarchical representation of critical subsystems. Depending on the system, you may consider developing a functional decomposition, assembly decomposition, or service-based decomposition. | E12: x | R12: =IF(E12="x",12,IF(F12="x",11,IF(G12="x",10,IF(H12="x",9,IF(I12="x",8,IF(J12="x",7,IF(K12="x",6,IF(L12="x",5,IF(M12="x",4,IF(N12="x",3,IF(O12="x",2,IF(P12="x",1,IF(Q12="x",0,""))))))))))))) -> 12
A13: Comments
A14: Design Development | B14: =Data!A41 -> 5.4 | C14: =Data!B41 -> Final Design Description | D14: =Data!C41 -> Describes all aspects of the final design and how it meets the client's requirements. | E14: x | R14: =IF(E14="x",12,IF(F14="x",11,IF(G14="x",10,IF(H14="x",9,IF(I14="x",8,IF(J14="x",7,IF(K14="x",6,IF(L14="x",5,IF(M14="x",4,IF(N14="x",3,IF(O14="x",2,IF(P14="x",1,IF(Q14="x",0,""))))))))))))) -> 12 | S14: 2 | T14: =S14*AVERAGE(R14:R17) -> 24
B15: =Data!A42 -> 5.5 | C15: =Data!B42 -> Design Calculations & Analysis Results | D15: =Data!C42 -> Provide and describe the analytical models used to support the design. (FEA, Electrical simulations, Mechanical analysis) Provide and describe the experiments and measurements that support the design. | E15: x | R15: =IF(E15="x",12,IF(F15="x",11,IF(G15="x",10,IF(H15="x",9,IF(I15="x",8,IF(J15="x",7,IF(K15="x",6,IF(L15="x",5,IF(M15="x",4,IF(N15="x",3,IF(O15="x",2,IF(P15="x",1,IF(Q15="x",0,""))))))))))))) -> 12
B16: =Data!A43 -> 5.6 | C16: =Data!B43 -> Mathematical Modeling (Lit review) | D16: =Data!C43 -> Define all analytical approaches to be used to support confirmation that your system design will meet the client requirements. | E16: x | R16: =IF(E16="x",12,IF(F16="x",11,IF(G16="x",10,IF(H16="x",9,IF(I16="x",8,IF(J16="x",7,IF(K16="x",6,IF(L16="x",5,IF(M16="x",4,IF(N16="x",3,IF(O16="x",2,IF(P16="x",1,IF(Q16="x",0,""))))))))))))) -> 12
B17: =Data!A44 -> 5.7 | C17: =Data!B44 -> Critical Issues & Risk Mitigation | D17: =Data!C44 -> Explains critical issues that have arisen. Translates critical issues into sequential action items. Explains the affect(s) on the critical path and schedule. | E17: x | R17: =IF(E17="x",12,IF(F17="x",11,IF(G17="x",10,IF(H17="x",9,IF(I17="x",8,IF(J17="x",7,IF(K17="x",6,IF(L17="x",5,IF(M17="x",4,IF(N17="x",3,IF(O17="x",2,IF(P17="x",1,IF(Q17="x",0,""))))))))))))) -> 12
A18: Comments
A19: Technical Design Documentation | B19: =Data!A46 -> 6.1 | C19: =Data!B46 -> Mechanical Design | D19: =Data!C46 -> Provides a mechanical description for the project design with sufficient detail for fabrication/manufacturing/assembly. The descriptions include tolerances, part numbering, and material specifications. Provides a manufacturing plan for each part. | E19: x | R19: =IF(E19="x",12,IF(F19="x",11,IF(G19="x",10,IF(H19="x",9,IF(I19="x",8,IF(J19="x",7,IF(K19="x",6,IF(L19="x",5,IF(M19="x",4,IF(N19="x",3,IF(O19="x",2,IF(P19="x",1,IF(Q19="x",0,""))))))))))))) -> 12 | S19: 2 | T19: =S19*AVERAGE(R19:R22) -> 24
B20: =Data!A47 -> 6.2 | C20: =Data!B47 -> Electrical Design | D20: =Data!C47 -> Provides an electrical description for the project design with sufficient detail for fabrication/manufacturing/assembly. Provides complete circuit diagrams. Evaluates the results of circuit breadboards. Provides complete wiring diagrams including cables and connectors. Provides a PC board layout ready for production including mounting points. | E20: x | R20: =IF(E20="x",12,IF(F20="x",11,IF(G20="x",10,IF(H20="x",9,IF(I20="x",8,IF(J20="x",7,IF(K20="x",6,IF(L20="x",5,IF(M20="x",4,IF(N20="x",3,IF(O20="x",2,IF(P20="x",1,IF(Q20="x",0,""))))))))))))) -> 12
B21: =Data!A48 -> 6.3 | C21: =Data!B48 -> Software & Programming | D21: =Data!C48 -> Provides a description of the software for the project with sufficient detail for reproducibility and troubleshooting. Includes complete flow diagrams including links and operating interfaces. | E21: x | R21: =IF(E21="x",12,IF(F21="x",11,IF(G21="x",10,IF(H21="x",9,IF(I21="x",8,IF(J21="x",7,IF(K21="x",6,IF(L21="x",5,IF(M21="x",4,IF(N21="x",3,IF(O21="x",2,IF(P21="x",1,IF(Q21="x",0,""))))))))))))) -> 12
B22: =Data!A50 -> 6.5 | C22: =Data!B50 -> System Design Bill of Materials (BOM) | D22: =Data!C50 -> Provide a completed Design Bill of Materials table that defines each system grouping with its associated assemblies and individual parts fully defined. Each line item in the table has an identifiable part numbering system created by the team. | E22: x | R22: =IF(E22="x",12,IF(F22="x",11,IF(G22="x",10,IF(H22="x",9,IF(I22="x",8,IF(J22="x",7,IF(K22="x",6,IF(L22="x",5,IF(M22="x",4,IF(N22="x",3,IF(O22="x",2,IF(P22="x",1,IF(Q22="x",0,""))))))))))))) -> 12
A23: Comments
A24: Project Budget & Expenses | B24: =Data!A57 -> 8.4 | C24: =Data!B57 -> Established Project Budget | D24: =Data!C57 -> Describe the amount of funds that will be available to procure all necessary parts and materials to build your prototype. | E24: x | R24: =IF(E24="x",12,IF(F24="x",11,IF(G24="x",10,IF(H24="x",9,IF(I24="x",8,IF(J24="x",7,IF(K24="x",6,IF(L24="x",5,IF(M24="x",4,IF(N24="x",3,IF(O24="x",2,IF(P24="x",1,IF(Q24="x",0,""))))))))))))) -> 12 | T24: =AVERAGE(R24:R26) -> 12
B25: =Data!A58 -> 8.5 | C25: =Data!B58 -> Prototype Parts Expense | D25: =Data!C58 -> Tabulate the total expenses for the various systems of your project, such as, ‘Mechanical Parts’, ‘Electrical Components’, ‘Supplies’, ‘Electrical Suppliers’, ‘Special Tools”, etc. | E25: x | R25: =IF(E25="x",12,IF(F25="x",11,IF(G25="x",10,IF(H25="x",9,IF(I25="x",8,IF(J25="x",7,IF(K25="x",6,IF(L25="x",5,IF(M25="x",4,IF(N25="x",3,IF(O25="x",2,IF(P25="x",1,IF(Q25="x",0,""))))))))))))) -> 12
B26: =Data!A59 -> 8.6 | C26: =Data!B59 -> Budget Summary | D26: =Data!C59 -> Provide a summary of the status of all expenses and available budget amounts. | E26: x | R26: =IF(E26="x",12,IF(F26="x",11,IF(G26="x",10,IF(H26="x",9,IF(I26="x",8,IF(J26="x",7,IF(K26="x",6,IF(L26="x",5,IF(M26="x",4,IF(N26="x",3,IF(O26="x",2,IF(P26="x",1,IF(Q26="x",0,""))))))))))))) -> 12
A27: Comments
A28: Project Management | B28: =Data!A65 -> 10.1 | C28: =Data!B65 -> Project Schedule | D28: =Data!C65 -> Task descriptions contain an acceptable level of detail. Task predecessor links properly used with no open-ended tasks. Task progress bar properly used to indicate % completion status of active tasks. All tasks set to Auto-Schedule mode. All Resource Names added. Milestones identified and properly linked. All task flow in a chronological order. | E28: x | R28: =IF(E28="x",12,IF(F28="x",11,IF(G28="x",10,IF(H28="x",9,IF(I28="x",8,IF(J28="x",7,IF(K28="x",6,IF(L28="x",5,IF(M28="x",4,IF(N28="x",3,IF(O28="x",2,IF(P28="x",1,IF(Q28="x",0,""))))))))))))) -> 12 | T28: =AVERAGE(R28:R29) -> 12
B29: =Data!A66 -> 10.2 | C29: =Data!B66 -> Gantt Charts & Critical Path | D29: =Data!C66&" 3 Tasks." -> Gantt Chart(s): Properly formatted to clearly define project status details and all information in the Gantt Charts is aligned with the Gate requirements. Task level information clearly indicates an appropriate level of detail. Chart types are properly created as defined in the Project Schedule Guidelines. Critical Path: MS Project able to calculate critical path based on existing tasks and predecessor structure. Clearly defined and shown using the Level 3 chart format. Gantt Charts content should be To gate 3 Tasks. | E29: x | R29: =IF(E29="x",12,IF(F29="x",11,IF(G29="x",10,IF(H29="x",9,IF(I29="x",8,IF(J29="x",7,IF(K29="x",6,IF(L29="x",5,IF(M29="x",4,IF(N29="x",3,IF(O29="x",2,IF(P29="x",1,IF(Q29="x",0,""))))))))))))) -> 12
A30: Comments | B30: Well prepared presentation. Please remember to introduce the separate objectives of the different team members. | R30: Total Points | T30: =SUM(T4:T29) -> 96
R31: Points Available | T31: 96
R32: Grade % | T32: =T30/T31 -> 1

Sheet G3P
A2: Gate 3 Concept Demonstration Video
A3: Category | B3: Report Sec. # | C3: Title | D3: Requirements (Additional information provided in Guidelines_Report.doc) | E3: Meets Expectations (12) | F3: (11) | G3: (10) | H3: (9) | I3: (8) | J3: (7) | K3: (6) | L3: (5) | M3: (4) | N3: (3) | O3: (2) | P3: (1) | Q3: No Evidence (0) | R3: Score (0-12) | S3: Weight | T3: Avg. Score
A4: Overall Presentation | C4: =Data!B11 -> Oral Presentation Skill | D4: =Data!C11 -> Clear enunciation when discussing engineering design. All members are participating. Smooth transitions between topics and presenters. | E4: x | R4: =IF(E4="x",12,IF(F4="x",11,IF(G4="x",10,IF(H4="x",9,IF(I4="x",8,IF(J4="x",7,IF(K4="x",6,IF(L4="x",5,IF(M4="x",4,IF(N4="x",3,IF(O4="x",2,IF(P4="x",1,IF(Q4="x",0,""))))))))))))) -> 12 | S4: 1.5 | T4: =AVERAGE(R4:R6)*S4 -> 18
C5: =Data!B12 -> Audio / Visual Quality of Presentation | D5: =Data!C12 -> Figures and tables in engineering format, free of spelling and grammatical errors, data presented is well-organized and defined in tabular or graphical form. Annotations are used to describe key points of photos and graphics. All slides are labeled with page numbers and consistent formatting between slides. Audio quality good no background noise or distractions. | E5: x | R5: =IF(E5="x",12,IF(F5="x",11,IF(G5="x",10,IF(H5="x",9,IF(I5="x",8,IF(J5="x",7,IF(K5="x",6,IF(L5="x",5,IF(M5="x",4,IF(N5="x",3,IF(O5="x",2,IF(P5="x",1,IF(Q5="x",0,""))))))))))))) -> 12
C6: =Data!B13 -> References | D6: =Data!C13 -> References (in-text and bibliography) properly cited in IEEE style. Proper use of the Zotero citation management tool | E6: x | R6: =IF(E6="x",12,IF(F6="x",11,IF(G6="x",10,IF(H6="x",9,IF(I6="x",8,IF(J6="x",7,IF(K6="x",6,IF(L6="x",5,IF(M6="x",4,IF(N6="x",3,IF(O6="x",2,IF(P6="x",1,IF(Q6="x",0,""))))))))))))) -> 12
A7: Comments
A8: Project Definition | B8: =Data!A23 -> 1.1 | C8: =Data!B23 -> Problem Description | D8: =Data!C23 -> Includes context to the problem, reason for the problem, need for this project, defines who is impacted by the problem (customer / market) and how. | E8: x | R8: =IF(E8="x",12,IF(F8="x",11,IF(G8="x",10,IF(H8="x",9,IF(I8="x",8,IF(J8="x",7,IF(K8="x",6,IF(L8="x",5,IF(M8="x",4,IF(N8="x",3,IF(O8="x",2,IF(P8="x",1,IF(Q8="x",0,""))))))))))))) -> 12 | S8: 1 | T8: =AVERAGE(R8:R11)*S8 -> 12
B9: =Data!A24 -> 1.2 | C9: =Data!B24 -> Problem Statement | D9: =Data!C24 -> Describes the problem in technical detail and Quantifies the impact on the customer/market. Introduce critical performance metrics. Defines the end-user population (e.g., person, environment, or organization). | E9: x | R9: =IF(E9="x",12,IF(F9="x",11,IF(G9="x",10,IF(H9="x",9,IF(I9="x",8,IF(J9="x",7,IF(K9="x",6,IF(L9="x",5,IF(M9="x",4,IF(N9="x",3,IF(O9="x",2,IF(P9="x",1,IF(Q9="x",0,""))))))))))))) -> 12
B10: =Data!A25 -> 1.3 | C10: =Data!B25 -> Scope of Work | D10: =Data!C25 -> Describes the approach to solve this problem, the projected timeline plan, and the assumptions, limitations, and constraints of the project. Describes the services and/or materials to be obtained from the client. | E10: X | R10: =IF(E10="x",12,IF(F10="x",11,IF(G10="x",10,IF(H10="x",9,IF(I10="x",8,IF(J10="x",7,IF(K10="x",6,IF(L10="x",5,IF(M10="x",4,IF(N10="x",3,IF(O10="x",2,IF(P10="x",1,IF(Q10="x",0,""))))))))))))) -> 12
B11: =Data!A38 -> 5.1 | C11: =Data!B38 -> System Decomposition | D11: =Data!C38 -> Decompose the complexity of the system/problem by describing its constituent components. Break down the complex system/problem into smaller, more manageable parts by building a hierarchical representation of critical subsystems. Depending on the system, you may consider developing a functional decomposition, assembly decomposition, or service-based decomposition. | E11: x | R11: =IF(E11="x",12,IF(F11="x",11,IF(G11="x",10,IF(H11="x",9,IF(I11="x",8,IF(J11="x",7,IF(K11="x",6,IF(L11="x",5,IF(M11="x",4,IF(N11="x",3,IF(O11="x",2,IF(P11="x",1,IF(Q11="x",0,""))))))))))))) -> 12
A12: Comments
A13: Design Development | C13: Concept Evolution (Inspiration + Creativity) | D13: =Data!C21 -> Presents the evolution of your design by illustrating the developments made throughout the exploratory/conceptual/down-selection design phases. Points out the strengths and weaknesses of each design. Provides evidence to validate the concept selection. | E13: x | R13: =IF(E13="x",12,IF(F13="x",11,IF(G13="x",10,IF(H13="x",9,IF(I13="x",8,IF(J13="x",7,IF(K13="x",6,IF(L13="x",5,IF(M13="x",4,IF(N13="x",3,IF(O13="x",2,IF(P13="x",1,IF(Q13="x",0,""))))))))))))) -> 12 | S13: 2.5 | T13: =AVERAGE(R13:R15)*S13 -> 30
C14: Quality of Science | D14: Demonstrates critical thinking skills to evaluate technical and market viability. Is the problem and assessment structured/justified. Standards & industrial accepted methods of assessment, logic, reasoning, (core principles) evidence. | E14: x | R14: =IF(E14="x",12,IF(F14="x",11,IF(G14="x",10,IF(H14="x",9,IF(I14="x",8,IF(J14="x",7,IF(K14="x",6,IF(L14="x",5,IF(M14="x",4,IF(N14="x",3,IF(O14="x",2,IF(P14="x",1,IF(Q14="x",0,""))))))))))))) -> 12
C15: Quality of Prototype & Model | D15: Prototype demonstrates proof-of-concept for at least 1 key functional and/or customer requirement. Demo of critical principles, scaled, off-the-shelf, | E15: x | R15: =IF(E15="x",12,IF(F15="x",11,IF(G15="x",10,IF(H15="x",9,IF(I15="x",8,IF(J15="x",7,IF(K15="x",6,IF(L15="x",5,IF(M15="x",4,IF(N15="x",3,IF(O15="x",2,IF(P15="x",1,IF(Q15="x",0,""))))))))))))) -> 12
A16: Comments
A17: Preliminary Results | C17: =Data!B16 -> Comparison of results | D17: =Data!C16 -> Compare your experimental results to the theory. Describe the mathematical model(s) used to predict product performance (e.g., FEA, Electrical simulations, Mechanical analysis). Describe the experiments and measurements that support the design methodology. | E17: x | R17: =IF(E17="x",12,IF(F17="x",11,IF(G17="x",10,IF(H17="x",9,IF(I17="x",8,IF(J17="x",7,IF(K17="x",6,IF(L17="x",5,IF(M17="x",4,IF(N17="x",3,IF(O17="x",2,IF(P17="x",1,IF(Q17="x",0,""))))))))))))) -> 12 | S17: 2.5 | T17: =AVERAGE(R17:R19)*S17 -> 30
C18: Interpretation of Results | D18: =Data!C70 -> List most important lessons learned by sharing experiences of how new and improved techniques or processes were developed and how they were instrumental in achieving your design requirements. | E18: X | R18: =IF(E18="x",12,IF(F18="x",11,IF(G18="x",10,IF(H18="x",9,IF(I18="x",8,IF(J18="x",7,IF(K18="x",6,IF(L18="x",5,IF(M18="x",4,IF(N18="x",3,IF(O18="x",2,IF(P18="x",1,IF(Q18="x",0,""))))))))))))) -> 12
C19: Future Work | D19: Describe the next steps that you would take in this work. Formulate any questions that your results may raise and whether alternative steps should be considered in future work. | E19: X | R19: =IF(E19="x",12,IF(F19="x",11,IF(G19="x",10,IF(H19="x",9,IF(I19="x",8,IF(J19="x",7,IF(K19="x",6,IF(L19="x",5,IF(M19="x",4,IF(N19="x",3,IF(O19="x",2,IF(P19="x",1,IF(Q19="x",0,""))))))))))))) -> 12
A20: Comments
A21: Demonstration | C21: =Data!B14 -> Demo Video | D21: =Data!C14 -> Video uploaded into the proper location(s) | E21: x | R21: =IF(E21="x",12,IF(F21="x",11,IF(G21="x",10,IF(H21="x",9,IF(I21="x",8,IF(J21="x",7,IF(K21="x",6,IF(L21="x",5,IF(M21="x",4,IF(N21="x",3,IF(O21="x",2,IF(P21="x",1,IF(Q21="x",0,""))))))))))))) -> 12 | S21: 0.5 | T21: =AVERAGE(R21:R21)*S21 -> 6
A22: Comments | R22: Total Points | T22: =SUM(T4:T21) -> 96
R23: Points Available | T23: 96
R24: Grade % | T24: =T22/T23 -> 1

Sheet G4R
A2: Gate 4 Technical Report Rubric
A3: Category | B3: Report Sec. # | C3: Title | D3: Requirements (Additional information provided in Guidelines_Report.doc) | E3: Meets Expectations (12) | F3: (11) | G3: (10) | H3: (9) | I3: (8) | J3: (7) | K3: (6) | L3: (5) | M3: (4) | N3: (3) | O3: (2) | P3: (1) | Q3: No Evidence (0) | R3: Score (0-12) | S3: Weight | T3: Avg. Score
A4: Updated Sections based on feedback from Previous Gate(s) | B4: =Data!A6 -> ii | C4: =Data!B6 -> Executive Summary | D4: Gate 4 adjusted based upon project status and feedback from previous Gate Reports. | E4: x | R4: =IF(E4="x",12,IF(F4="x",11,IF(G4="x",10,IF(H4="x",9,IF(I4="x",8,IF(J4="x",7,IF(K4="x",6,IF(L4="x",5,IF(M4="x",4,IF(N4="x",3,IF(O4="x",2,IF(P4="x",1,IF(Q4="x",0,""))))))))))))) -> 12 | S4: 1 | T4: =AVERAGE(R4:R13)*S4 -> 12
B5: =Data!A28 -> 2.1 | C5: =Data!B28 -> Review of the Problem Area | E5: x | R5: =IF(E5="x",12,IF(F5="x",11,IF(G5="x",10,IF(H5="x",9,IF(I5="x",8,IF(J5="x",7,IF(K5="x",6,IF(L5="x",5,IF(M5="x",4,IF(N5="x",3,IF(O5="x",2,IF(P5="x",1,IF(Q5="x",0,""))))))))))))) -> 12
B6: =Data!A29 -> 2.2 | C6: =Data!B29 -> Review of State-of-the-Art | E6: x | R6: =IF(E6="x",12,IF(F6="x",11,IF(G6="x",10,IF(H6="x",9,IF(I6="x",8,IF(J6="x",7,IF(K6="x",6,IF(L6="x",5,IF(M6="x",4,IF(N6="x",3,IF(O6="x",2,IF(P6="x",1,IF(Q6="x",0,""))))))))))))) -> 12
B7: =Data!A31 -> 3.1 | C7: =Data!B31 -> Requirements Matrix | E7: x | R7: =IF(E7="x",12,IF(F7="x",11,IF(G7="x",10,IF(H7="x",9,IF(I7="x",8,IF(J7="x",7,IF(K7="x",6,IF(L7="x",5,IF(M7="x",4,IF(N7="x",3,IF(O7="x",2,IF(P7="x",1,IF(Q7="x",0,""))))))))))))) -> 12
B8: =Data!A32 -> 3.2 | C8: =Data!B32 -> Exploratory Concepts | E8: x | R8: =IF(E8="x",12,IF(F8="x",11,IF(G8="x",10,IF(H8="x",9,IF(I8="x",8,IF(J8="x",7,IF(K8="x",6,IF(L8="x",5,IF(M8="x",4,IF(N8="x",3,IF(O8="x",2,IF(P8="x",1,IF(Q8="x",0,""))))))))))))) -> 12
B9: =Data!A33 -> 3.3 | C9: =Data!B33 -> Resource Requirements | E9: x | R9: =IF(E9="x",12,IF(F9="x",11,IF(G9="x",10,IF(H9="x",9,IF(I9="x",8,IF(J9="x",7,IF(K9="x",6,IF(L9="x",5,IF(M9="x",4,IF(N9="x",3,IF(O9="x",2,IF(P9="x",1,IF(Q9="x",0,""))))))))))))) -> 12
B10: =Data!A39 -> 5.2 | C10: =Data!B39 -> Conceptual Design | R10: =IF(E10="x",12,IF(F10="x",11,IF(G10="x",10,IF(H10="x",9,IF(I10="x",8,IF(J10="x",7,IF(K10="x",6,IF(L10="x",5,IF(M10="x",4,IF(N10="x",3,IF(O10="x",2,IF(P10="x",1,IF(Q10="x",0,"")))))))))))))
B11: =Data!A40 -> 5.3 | C11: =Data!B40 -> Down Selection Process | E11: x | R11: =IF(E11="x",12,IF(F11="x",11,IF(G11="x",10,IF(H11="x",9,IF(I11="x",8,IF(J11="x",7,IF(K11="x",6,IF(L11="x",5,IF(M11="x",4,IF(N11="x",3,IF(O11="x",2,IF(P11="x",1,IF(Q11="x",0,""))))))))))))) -> 12
B12: =Data!A67 -> 10.3 | C12: =Data!B67 -> MS Teams File Documentation | E12: x | R12: =IF(E12="x",12,IF(F12="x",11,IF(G12="x",10,IF(H12="x",9,IF(I12="x",8,IF(J12="x",7,IF(K12="x",6,IF(L12="x",5,IF(M12="x",4,IF(N12="x",3,IF(O12="x",2,IF(P12="x",1,IF(Q12="x",0,""))))))))))))) -> 12
B13: A1-4 | C13: Update Appendices | E13: x | R13: =IF(E13="x",12,IF(F13="x",11,IF(G13="x",10,IF(H13="x",9,IF(I13="x",8,IF(J13="x",7,IF(K13="x",6,IF(L13="x",5,IF(M13="x",4,IF(N13="x",3,IF(O13="x",2,IF(P13="x",1,IF(Q13="x",0,""))))))))))))) -> 12
A14: Design Development | B14: =Data!A41 -> 5.4 | C14: =Data!B41 -> Final Design Description | D14: =Data!C41 -> Describes all aspects of the final design and how it meets the client's requirements. | E14: x | R14: =IF(E14="x",12,IF(F14="x",11,IF(G14="x",10,IF(H14="x",9,IF(I14="x",8,IF(J14="x",7,IF(K14="x",6,IF(L14="x",5,IF(M14="x",4,IF(N14="x",3,IF(O14="x",2,IF(P14="x",1,IF(Q14="x",0,""))))))))))))) -> 12 | S14: 1 | T14: =AVERAGE(R14:R17)*S14 -> 12
B15: =Data!A42 -> 5.5 | C15: =Data!B42 -> Design Calculations & Analysis Results | D15: =Data!C42 -> Provide and describe the analytical models used to support the design. (FEA, Electrical simulations, Mechanical analysis) Provide and describe the experiments and measurements that support the design. | E15: x | R15: =IF(E15="x",12,IF(F15="x",11,IF(G15="x",10,IF(H15="x",9,IF(I15="x",8,IF(J15="x",7,IF(K15="x",6,IF(L15="x",5,IF(M15="x",4,IF(N15="x",3,IF(O15="x",2,IF(P15="x",1,IF(Q15="x",0,""))))))))))))) -> 12
B16: =Data!A43 -> 5.6 | C16: =Data!B43 -> Mathematical Modeling (Lit review) | D16: =Data!C43 -> Define all analytical approaches to be used to support confirmation that your system design will meet the client requirements. | E16: x | R16: =IF(E16="x",12,IF(F16="x",11,IF(G16="x",10,IF(H16="x",9,IF(I16="x",8,IF(J16="x",7,IF(K16="x",6,IF(L16="x",5,IF(M16="x",4,IF(N16="x",3,IF(O16="x",2,IF(P16="x",1,IF(Q16="x",0,""))))))))))))) -> 12
B17: =Data!A44 -> 5.7 | C17: =Data!B44 -> Critical Issues & Risk Mitigation | D17: =Data!C44 -> Explains critical issues that have arisen. Translates critical issues into sequential action items. Explains the affect(s) on the critical path and schedule. | E17: x | R17: =IF(E17="x",12,IF(F17="x",11,IF(G17="x",10,IF(H17="x",9,IF(I17="x",8,IF(J17="x",7,IF(K17="x",6,IF(L17="x",5,IF(M17="x",4,IF(N17="x",3,IF(O17="x",2,IF(P17="x",1,IF(Q17="x",0,""))))))))))))) -> 12
A18: Technical Documentation | B18: =Data!A46 -> 6.1 | C18: =Data!B46 -> Mechanical Design | D18: =Data!C46 -> Provides a mechanical description for the project design with sufficient detail for fabrication/manufacturing/assembly. The descriptions include tolerances, part numbering, and material specifications. Provides a manufacturing plan for each part. | E18: x | R18: =IF(E18="x",12,IF(F18="x",11,IF(G18="x",10,IF(H18="x",9,IF(I18="x",8,IF(J18="x",7,IF(K18="x",6,IF(L18="x",5,IF(M18="x",4,IF(N18="x",3,IF(O18="x",2,IF(P18="x",1,IF(Q18="x",0,""))))))))))))) -> 12 | S18: 1.5 | T18: =AVERAGE(R18:R22)*S18 -> 18
B19: =Data!A47 -> 6.2 | C19: =Data!B47 -> Electrical Design | D19: =Data!C47 -> Provides an electrical description for the project design with sufficient detail for fabrication/manufacturing/assembly. Provides complete circuit diagrams. Evaluates the results of circuit breadboards. Provides complete wiring diagrams including cables and connectors. Provides a PC board layout ready for production including mounting points. | E19: x | R19: =IF(E19="x",12,IF(F19="x",11,IF(G19="x",10,IF(H19="x",9,IF(I19="x",8,IF(J19="x",7,IF(K19="x",6,IF(L19="x",5,IF(M19="x",4,IF(N19="x",3,IF(O19="x",2,IF(P19="x",1,IF(Q19="x",0,""))))))))))))) -> 12
B20: =Data!A48 -> 6.3 | C20: =Data!B48 -> Software & Programming | D20: =Data!C48 -> Provides a description of the software for the project with sufficient detail for reproducibility and troubleshooting. Includes complete flow diagrams including links and operating interfaces. | E20: x | R20: =IF(E20="x",12,IF(F20="x",11,IF(G20="x",10,IF(H20="x",9,IF(I20="x",8,IF(J20="x",7,IF(K20="x",6,IF(L20="x",5,IF(M20="x",4,IF(N20="x",3,IF(O20="x",2,IF(P20="x",1,IF(Q20="x",0,""))))))))))))) -> 12
